<?xml version="1.0" encoding="utf-8"?>
<!-- =================================================================================== -->
<!-- |    This document was autogenerated by xacro from mini_akm.xacro                 | -->
<!-- |    EDITING THIS FILE BY HAND IS NOT RECOMMENDED                                 | -->
<!-- =================================================================================== -->
<robot name="wheeltec">
  <!--define base_footprint-->
  <link name="base_footprint"/>
  <!--define fixed base_footprint_joint -->
  <joint name="base_footprint_joint" type="fixed">
    <origin rpy="0 0 0" xyz="0 0 0.025"/>
    <parent link="base_footprint"/>
    <child link="base_link"/>
  </joint>
  <!--define base_link -->
  <link name="base_link">
    <inertial>
      <origin rpy="0 0 0" xyz="-0.016347 0.00073329 0.026157"/>
      <mass value="1.0"/>
      <inertia ixx="0.0216666666667" ixy="0" ixz="0" iyy="0.0508333333333" iyz="0" izz="0.0308333333333"/>
    </inertial>
    <!--visual-->
    <visual>
      <origin rpy="0 0 0" xyz="0 0 0"/>
      <geometry>
        <mesh filename="package://wheeltec_description/meshes/mini_akm/base_link.STL"/>
      </geometry>
      <material name="white"/>
    </visual>
    <!--collision-->
    <collision>
      <origin rpy="0 0 0" xyz="0 0 0"/>
      <geometry>
        <mesh filename="package://wheeltec_description/meshes/mini_akm/base_link.STL"/>
      </geometry>
    </collision>
  </link>
  <!-- Defining the colors used in this robot -->
  <material name="black">
    <color rgba="0.0 0.0 0.0 1.0"/>
  </material>
  <material name="blue">
    <color rgba="0.0 0.0 0.8 1.0"/>
  </material>
  <material name="green">
    <color rgba="0.0 0.8 0.0 1.0"/>
  </material>
  <material name="grey">
    <color rgba="0.2 0.2 0.2 1.0"/>
  </material>
  <material name="white">
    <color rgba="1.0 1.0 1.0 1.0"/>
  </material>
  <!--define the base_link in Gazebo -->
  <gazebo reference="base_link">
    <material>Gazebo/Grey</material>
  </gazebo>
  <!-- Defining the control plugin used in this robot -->
  <gazebo>
    <plugin filename="libgazebo_ros_control.so" name="gazebo_ros_control">
      <robotNamespace>/wheeltec</robotNamespace>
      <robotSimType>gazebo_ros_control/DefaultRobotHWSim</robotSimType>
      <legacyModeNS>true</legacyModeNS>
    </plugin>
  </gazebo>
  <!-- rplidar joint-->
  <joint name="rplidar_joint" type="fixed">
    <origin rpy="0 0 0" xyz="0.051872 0.00011578 0.1306"/>
    <parent link="base_link"/>
    <child link="laser_link"/>
  </joint>
  <!-- camera joint-->
  <joint name="camera_frame_joint" type="fixed">
    <origin rpy="0 0 0" xyz="0.1402 0.00021887 0.093025"/>
    <parent link="base_link"/>
    <child link="camera_link"/>
  </joint>
  <joint name="imu_joint" type="fixed">
    <origin rpy="0 0 0" xyz="-0.03 0 0.06"/>
    <parent link="base_link"/>
    <child link="imu_link"/>
  </joint>
  <!-- Create laser reference frame -->
  <link name="laser_link">
    <inertial>
      <origin rpy="0 0 0" xyz="-0.016347 0.00073329 0.026157"/>
      <mass value="0.001"/>
      <inertia ixx="1.66666666667e-10" ixy="0" ixz="0" iyy="1.66666666667e-10" iyz="0" izz="1.66666666667e-10"/>
    </inertial>
    <visual>
      <origin rpy="0 0 0" xyz=" 0 0 0 "/>
      <geometry>
        <mesh filename="package://wheeltec_description/meshes/mini_akm/rplidar_link.STL"/>
      </geometry>
      <material name="black"/>
    </visual>
    <collision>
      <origin rpy="0 0 0" xyz="0 0 0"/>
      <geometry>
        <mesh filename="package://wheeltec_description/meshes/mini_akm/rplidar_link.STL"/>
      </geometry>
    </collision>
  </link>
  <gazebo reference="laser_link">
    <material>Gazebo/Black</material>
  </gazebo>
  <gazebo reference="laser_link">
    <sensor name="rplidar" type="ray">
      <pose>0 0 0 0 0 0</pose>
      <visualize>false</visualize>
      <update_rate>40</update_rate>
      <ray>
        <scan>
          <horizontal>
            <samples>720</samples>
            <resolution>1</resolution>
            <min_angle>-3.14159265359</min_angle>
            <max_angle>3.14159265359</max_angle>
          </horizontal>
        </scan>
        <range>
          <min>0.10</min>
          <max>30.0</max>
          <resolution>0.01</resolution>
        </range>
        <noise>
          <type>gaussian</type>
          <mean>0.0</mean>
          <stddev>0.0</stddev>
        </noise>
      </ray>
      <plugin filename="libgazebo_ros_laser.so" name="gazebo_rplidar">
        <topicName>/scan</topicName>
        <frameName>laser_link</frameName>
      </plugin>
    </sensor>
  </gazebo>
  <link name="imu_link">
    <inertial>
      <mass value="0.001"/>
      <origin xyz="0 0 0"/>
      <inertia ixx="0.00001" ixy="0.0" ixz="0.0" iyy="0.00001" iyz="0.0" izz="0.00001"/>
    </inertial>
    <visual>
      <origin rpy="0 0 0" xyz=" 0 0 0 "/>
      <geometry>
        <box size="0.01 0.01 0.01"/>
      </geometry>
      <material name="black"/>
    </visual>
    <collision>
      <origin rpy="0 0 0" xyz="0.0 0.0 0.0"/>
      <geometry>
        <box size="0.02 0.02 0.01"/>
      </geometry>
    </collision>
  </link>
  <gazebo reference="imu_link">
    <material>Gazebo/Black</material>
  </gazebo>
  <gazebo reference="imu_link">
    <gravity>true</gravity>
    <sensor name="imu_sensor" type="imu">
      <always_on>true</always_on>
      <update_rate>100</update_rate>
      <visualize>true</visualize>
      <topic>/imu_data</topic>
      <plugin filename="libgazebo_ros_imu_sensor.so" name="imu_plugin">
        <topicName>/imu_data</topicName>
        <bodyName>imu_link</bodyName>
        <updateRateHZ>100.0</updateRateHZ>
        <gaussianNoise>0.0</gaussianNoise>
        <xyzOffset>0 0 0</xyzOffset>
        <rpyOffset>0 0 0</rpyOffset>
        <frameName>imu_link</frameName>
      </plugin>
      <pose>0 0 0 0 0 0</pose>
    </sensor>
  </gazebo>
  <!--Defining camera_link -->
  <!-- Add mesh for camera -->
  <link name="camera_link">
    <inertial>
      <origin rpy="0 0 0" xyz="-0.016347 0.00073329 0.026157"/>
      <mass value="0.001"/>
      <inertia ixx="1.66666666667e-10" ixy="0" ixz="0" iyy="1.66666666667e-10" iyz="0" izz="1.66666666667e-10"/>
    </inertial>
    <visual>
      <origin rpy="0 0 0 " xyz="0 0 0"/>
      <geometry>
        <mesh filename="package://wheeltec_description/meshes/mini_akm/camera_link.STL"/>
      </geometry>
      <material name="white"/>
    </visual>
    <collision>
      <origin rpy="0 0 0 " xyz="0 0 0"/>
      <geometry>
        <mesh filename="package://wheeltec_description/meshes/mini_akm/camera_link.STL"/>
      </geometry>
    </collision>
  </link>
  <joint name="camera_optical_joint" type="fixed">
    <origin rpy="-1.57079632679 0 -1.57079632679" xyz="0 0 0"/>
    <parent link="camera_link"/>
    <child link="camera_frame_optical"/>
  </joint>
  <link name="camera_frame_optical"/>
  <gazebo reference="camera_link">
    <material>Gazebo/Grey</material>
    <sensor name="camera" type="depth">
      <always_on>true</always_on>
      <update_rate>20.0</update_rate>
      <camera>
        <horizontal_fov>1.04716666667</horizontal_fov>
        <image>
          <format>R8G8B8</format>
          <width>640</width>
          <height>480</height>
        </image>
        <clip>
          <near>0.05</near>
          <far>8.0</far>
        </clip>
        <noise>
          <type>gaussian</type>
          <mean>0.0</mean>
          <stddev>0.007</stddev>
        </noise>
      </camera>
      <plugin filename="libgazebo_ros_openni_kinect.so" name="astra_camera_controller">
        <cameraName>camera</cameraName>
        <alwaysOn>true</alwaysOn>
        <updateRate>10</updateRate>
        <imageTopicName>rgb/image_raw</imageTopicName>
        <depthImageTopicName>depth/image_raw</depthImageTopicName>
        <pointCloudTopicName>depth/points</pointCloudTopicName>
        <cameraInfoTopicName>rgb/camera_info</cameraInfoTopicName>
        <depthImageCameraInfoTopicName>depth/camera_info</depthImageCameraInfoTopicName>
        <frameName>camera_frame_optical</frameName>
        <baseline>0.1</baseline>
        <distortion_k1>0.0</distortion_k1>
        <distortion_k2>0.0</distortion_k2>
        <distortion_k3>0.0</distortion_k3>
        <distortion_t1>0.0</distortion_t1>
        <distortion_t2>0.0</distortion_t2>
        <pointCloudCutoff>0.4</pointCloudCutoff>
      </plugin>
    </sensor>
  </gazebo>
  <link name="right_rear_wheel_link">
    <inertial>
      <origin rpy="0 0 0" xyz="-3.98258093170512E-11 -0.00279452473049574 1.19940203602287E-11"/>
      <mass value="0.0515533105453"/>
      <inertia ixx="1.99603833653634E-05" ixy="1.47023522649957E-14" ixz="1.56178238251791E-10" iyy="3.41116766443603E-05" iyz="-1.59750652595274E-15" izz="1.99606952584451E-05"/>
    </inertial>
    <visual>
      <origin rpy="0 0 0" xyz="0 0 0"/>
      <geometry>
        <mesh filename="package://wheeltec_description/meshes/mini_akm/right_rear_wheel_link.STL"/>
      </geometry>
      <material name="black"/>
    </visual>
    <collision>
      <origin rpy="0 0 0" xyz="0 0 0"/>
      <geometry>
        <mesh filename="package://wheeltec_description/meshes/mini_akm/right_rear_wheel_link.STL"/>
      </geometry>
    </collision>
  </link>
  <link name="left_rear_wheel_link">
    <inertial>
      <origin rpy="0 0 0" xyz="3.98258093170512E-11 0.00279452473049574 1.19940203602287E-11"/>
      <mass value="0.0515533105453"/>
      <inertia ixx="1.99603833653634E-05" ixy="1.47023522649957E-14" ixz="-1.56178238251791E-10" iyy="3.41116766443603E-05" iyz="1.59750652595274E-15" izz="1.99606952584451E-05"/>
    </inertial>
    <visual>
      <origin rpy="0 0 0" xyz="0 0 0"/>
      <geometry>
        <mesh filename="package://wheeltec_description/meshes/mini_akm/left_rear_wheel_link.STL"/>
      </geometry>
      <material name="black"/>
    </visual>
    <collision>
      <origin rpy="0 0 0" xyz="0 0 0"/>
      <geometry>
        <mesh filename="package://wheeltec_description/meshes/mini_akm/left_rear_wheel_link.STL"/>
      </geometry>
    </collision>
  </link>
  <link name="right_front_wheel_link">
    <inertial>
      <origin rpy="0 0 0" xyz="1.50883194827145E-11 -0.00228176069832715 1.40150807625972E-11"/>
      <mass value="0.0515533105453"/>
      <inertia ixx="1.91351003010526E-05" ixy="-4.51400783455223E-15" ixz="-2.66123995114195E-10" iyy="3.30131998434901E-05" iyz="-4.48462029754282E-15" izz="1.91374249680472E-05"/>
    </inertial>
    <visual>
      <origin rpy="0 0 0" xyz="0 0 0"/>
      <geometry>
        <mesh filename="package://wheeltec_description/meshes/mini_akm/right_front_wheel_link.STL"/>
      </geometry>
      <material name="black"/>
    </visual>
    <collision>
      <origin rpy="0 0 0" xyz="0 0 0"/>
      <geometry>
        <mesh filename="package://wheeltec_description/meshes/mini_akm/right_front_wheel_link.STL"/>
      </geometry>
    </collision>
  </link>
  <link name="left_front_wheel_link">
    <inertial>
      <origin rpy="0 0 0" xyz="1.50882639715633E-11 0.00228176069832718 -1.40150807625972E-11"/>
      <mass value="0.0515533105453"/>
      <inertia ixx="1.91343292762451E-05" ixy="4.51397364480803E-15" ixz="9.52734291190626E-10" iyy="3.30122388976539E-05" iyz="-4.48462116122782E-15" izz="1.91372350470185E-05"/>
    </inertial>
    <visual>
      <origin rpy="0 0 0" xyz="0 0 0"/>
      <geometry>
        <mesh filename="package://wheeltec_description/meshes/mini_akm/left_front_wheel_link.STL"/>
      </geometry>
      <material name="black"/>
    </visual>
    <collision>
      <origin rpy="0 0 0" xyz="0 0 0"/>
      <geometry>
        <mesh filename="package://wheeltec_description/meshes/mini_akm/left_front_wheel_link.STL"/>
      </geometry>
    </collision>
  </link>
  <joint name="right_rear_wheel_joint" type="continuous">
    <origin rpy="0 0 0" xyz="-0.069152 -0.083 0.0165"/>
    <parent link="base_link"/>
    <child link="right_rear_wheel_link"/>
    <axis rpy="0 0 0" xyz="0 1 0"/>
    <limit effort="3.9" velocity="38.70"/>
  </joint>
  <joint name="left_rear_wheel_joint" type="continuous">
    <origin rpy="0 0 0" xyz="-0.069152 0.083 0.0165"/>
    <parent link="base_link"/>
    <child link="left_rear_wheel_link"/>
    <axis rpy="0 0 0" xyz="0 1 0"/>
    <limit effort="3.9" velocity="38.70"/>
  </joint>
  <!--front axle carrier-->
  <link name="right_front_axle_carrier">
    <inertial>
      <mass value="0.01"/>
      <inertia ixx="0.001" ixy="0" ixz="0" iyy="0.001" iyz="0" izz="0.001"/>
    </inertial>
  </link>
  <joint name="right_front_wheel_joint" type="continuous">
    <origin rpy="0 0 0" xyz="0 0 0"/>
    <parent link="right_front_axle_carrier"/>
    <child link="right_front_wheel_link"/>
    <axis rpy="0 0 0" xyz="0 1 0"/>
    <limit effort="3.9" velocity="36.92"/>
  </joint>
  <joint name="right_steering_joint" type="revolute">
    <origin rpy="0 0 0" xyz="0.074098 -0.080997 0.013"/>
    <parent link="base_link"/>
    <child link="right_front_axle_carrier"/>
    <axis xyz="0 0 1"/>
    <limit effort="0.045" lower="-0.523281" upper="0.523281" velocity="4.5"/>
  </joint>
  <!--front axle carrier-->
  <link name="left_front_axle_carrier">
    <inertial>
      <mass value="0.01"/>
      <inertia ixx="0.001" ixy="0" ixz="0" iyy="0.001" iyz="0" izz="0.001"/>
    </inertial>
  </link>
  <joint name="left_front_wheel_joint" type="continuous">
    <origin rpy="0 0 0" xyz="0 0 0"/>
    <parent link="left_front_axle_carrier"/>
    <child link="left_front_wheel_link"/>
    <axis rpy="0 0 0" xyz="0 1 0"/>
    <limit effort="3.9" velocity="36.92"/>
  </joint>
  <joint name="left_steering_joint" type="revolute">
    <origin rpy="0 0 0" xyz="0.074098 0.081003 0.013"/>
    <parent link="base_link"/>
    <child link="left_front_axle_carrier"/>
    <axis xyz="0 0 1"/>
    <limit effort="0.045" lower="-0.523281" upper="0.523281" velocity="4.5"/>
  </joint>
  <gazebo reference="right_rear_wheel_link">
    <material>Gazebo/Black</material>
    <mu1>40</mu1>
    <mu2>40</mu2>
  </gazebo>
  <transmission name="right_rear_wheel_joint_trans">
    <type>transmission_interface/SimpleTransmission</type>
    <joint name="right_rear_wheel_joint">
      <hardwareInterface>hardware_interface/VelocityJointInterface</hardwareInterface>
    </joint>
    <actuator name="right_rear_wheel_joint_motor">
      <hardwareInterface>hardware_interface/VelocityJointInterface</hardwareInterface>
      <mechanicalReduction>1</mechanicalReduction>
    </actuator>
  </transmission>
  <gazebo reference="left_rear_wheel_link">
    <material>Gazebo/Black</material>
    <mu1>40</mu1>
    <mu2>40</mu2>
  </gazebo>
  <transmission name="left_rear_wheel_joint_trans">
    <type>transmission_interface/SimpleTransmission</type>
    <joint name="left_rear_wheel_joint">
      <hardwareInterface>hardware_interface/VelocityJointInterface</hardwareInterface>
    </joint>
    <actuator name="left_rear_wheel_joint_motor">
      <hardwareInterface>hardware_interface/VelocityJointInterface</hardwareInterface>
      <mechanicalReduction>1</mechanicalReduction>
    </actuator>
  </transmission>
  <gazebo reference="right_front_wheel_link">
    <material>Gazebo/Black</material>
    <mu1>40</mu1>
    <mu2>40</mu2>
  </gazebo>
  <transmission name="right_front_wheel_joint_trans">
    <type>transmission_interface/SimpleTransmission</type>
    <joint name="right_front_wheel_joint">
      <hardwareInterface>hardware_interface/VelocityJointInterface</hardwareInterface>
    </joint>
    <actuator name="right_front_wheel_joint_motor">
      <hardwareInterface>hardware_interface/VelocityJointInterface</hardwareInterface>
      <mechanicalReduction>1</mechanicalReduction>
    </actuator>
  </transmission>
  <gazebo reference="left_front_wheel_link">
    <material>Gazebo/Black</material>
    <mu1>40</mu1>
    <mu2>40</mu2>
  </gazebo>
  <transmission name="left_front_wheel_joint_trans">
    <type>transmission_interface/SimpleTransmission</type>
    <joint name="left_front_wheel_joint">
      <hardwareInterface>hardware_interface/VelocityJointInterface</hardwareInterface>
    </joint>
    <actuator name="left_front_wheel_joint_motor">
      <hardwareInterface>hardware_interface/VelocityJointInterface</hardwareInterface>
      <mechanicalReduction>1</mechanicalReduction>
    </actuator>
  </transmission>
  <transmission name="right_steering_trans">
    <type>transmission_interface/SimpleTransmission</type>
    <joint name="right_steering_joint">
      <hardwareInterface>hardware_interface/PositionJointInterface</hardwareInterface>
    </joint>
    <actuator name="right_steering_act">
      <hardwareInterface>hardware_interface/PositionJointInterface</hardwareInterface>
      <mechanicalReduction>1</mechanicalReduction>
    </actuator>
  </transmission>
  <transmission name="left_steering_trans">
    <type>transmission_interface/SimpleTransmission</type>
    <joint name="left_steering_joint">
      <hardwareInterface>hardware_interface/PositionJointInterface</hardwareInterface>
    </joint>
    <actuator name="left_steering_act">
      <hardwareInterface>hardware_interface/PositionJointInterface</hardwareInterface>
      <mechanicalReduction>1</mechanicalReduction>
    </actuator>
  </transmission>
</robot>

